Traceback (most recent call last):
  File "classification.py", line 67, in <module>
    Fire(main)
  File "/usr/local/lib/python3.6/dist-packages/fire/core.py", line 141, in Fire
    component_trace = _Fire(component, args, parsed_flag_args, context, name)
  File "/usr/local/lib/python3.6/dist-packages/fire/core.py", line 471, in _Fire
    target=component.__name__)
  File "/usr/local/lib/python3.6/dist-packages/fire/core.py", line 681, in _CallAndUpdateTrace
    component = fn(*varargs, **kwargs)
  File "classification.py", line 14, in main
    mnist = fetch_openml('mnist_784', version=1, cache=True)
  File "/usr/local/lib/python3.6/dist-packages/sklearn/datasets/_openml.py", line 729, in fetch_openml
    data_qualities = _get_data_qualities(data_id, data_home)
  File "/usr/local/lib/python3.6/dist-packages/sklearn/datasets/_openml.py", line 418, in _get_data_qualities
    data_home)
  File "/usr/local/lib/python3.6/dist-packages/sklearn/datasets/_openml.py", line 168, in _get_json_content_from_openml_api
    raise ValueError(error_message)
ValueError: Dataset with data_id 554 not found.
