Traceback (most recent call last):
  File "/usr/local/lib/python3.6/dist-packages/pandas/core/indexes/base.py", line 2895, in get_loc
    return self._engine.get_loc(casted_key)
  File "pandas/_libs/index.pyx", line 70, in pandas._libs.index.IndexEngine.get_loc
  File "pandas/_libs/index.pyx", line 101, in pandas._libs.index.IndexEngine.get_loc
  File "pandas/_libs/hashtable_class_helper.pxi", line 1675, in pandas._libs.hashtable.PyObjectHashTable.get_item
  File "pandas/_libs/hashtable_class_helper.pxi", line 1683, in pandas._libs.hashtable.PyObjectHashTable.get_item
KeyError: 'income_cat'

The above exception was the direct cause of the following exception:

Traceback (most recent call last):
  File "exercise.py", line 54, in <module>
    Fire(main)
  File "/usr/local/lib/python3.6/dist-packages/fire/core.py", line 138, in Fire
    component_trace = _Fire(component, args, parsed_flag_args, context, name)
  File "/usr/local/lib/python3.6/dist-packages/fire/core.py", line 468, in _Fire
    target=component.__name__)
  File "/usr/local/lib/python3.6/dist-packages/fire/core.py", line 672, in _CallAndUpdateTrace
    component = fn(*varargs, **kwargs)
  File "exercise.py", line 42, in main
    'Random': income_cat_proportions(test_set),
  File "exercise.py", line 51, in income_cat_proportions
    return data['income_cat'].value_counts()/len(data)
  File "/usr/local/lib/python3.6/dist-packages/pandas/core/frame.py", line 2906, in __getitem__
    indexer = self.columns.get_loc(key)
  File "/usr/local/lib/python3.6/dist-packages/pandas/core/indexes/base.py", line 2897, in get_loc
    raise KeyError(key) from err
KeyError: 'income_cat'
